# difference between throw ex and throw

In C#, `throw` is used to throw an exception, while `throw ex` is used to re-throw an exception with the same call stack and additional information about the error.

When you use `throw` to throw an exception, a new exception object is created and thrown. The call stack at the point where the exception is thrown is captured and stored in the exception object so that when the exception is caught and handled, the call stack information can be used to determine where the exception occurred.

On the other hand, when you use `throw ex` to re-throw an exception, the same exception object is thrown again, but with additional information about the error, such as a custom error message or additional data about the error. This can be useful in cases where you want to add more information to the exception object before it is caught and handled.

However, using `throw ex` can also have some drawbacks. When you re-throw an exception using `throw ex`, the original call stack information is lost and replaced with the current call stack information. This can make it harder to determine where the exception originated. Additionally, any outer try-catch blocks that were intended to catch the original exception will not be able to catch the re-thrown exception, since it is treated as a new exception object.

Here's an example to illustrate the difference:

```csharp
csharpCopy codetry
{
    // code that may throw an exception
}
catch (Exception ex)
{
    // re-throw the exception with additional information
    throw new Exception("An error occurred while processing the data.", ex);
}
```

In this example, if an exception is thrown in the try block, it will be caught in the catch block. The catch block then re-throws the same exception, but with an additional error message that describes what went wrong. When the exception is caught and handled elsewhere, the error message and the original call stack information will be available to help diagnose the issue.

If the catch block had been used `throw ex` instead of `throw new Exception("An error occurred while processing the data.", ex)`, the original call stack information would be lost, making it harder to determine where the exception originated. Additionally, any outer try-catch blocks that were intended to catch the original exception would not be able to catch the re-thrown exception, since it is treated as a new exception object.