# exception handling in c#

Exception handling is a mechanism in C# that allows a program to detect and respond to runtime errors, also known as exceptions, in a graceful and controlled manner. C# provides a robust set of features to handle exceptions, including try-catch blocks, throw statements, and exception filters.

The basic structure of a try-catch block in C# is as follows:

```csharp
csharpCopy codetry
{
    // Code that might throw an exception
}
catch (ExceptionType1 ex1)
{
    // Code to handle exception of type ExceptionType1
}
catch (ExceptionType2 ex2)
{
    // Code to handle exception of type ExceptionType2
}
//...
catch (Exception ex)
{
    // Code to handle all other exceptions
}
finally
{
    // Code that runs regardless of whether an exception is thrown or caught
}
```

Here's an example to illustrate the usage of exception handling in C#:

```csharp
csharpCopy codetry
{
    int x = int.Parse(Console.ReadLine());
    int y = int.Parse(Console.ReadLine());

    int result = x / y;
    Console.WriteLine($"Result: {result}");
}
catch (FormatException ex)
{
    Console.WriteLine("Invalid input format!");
}
catch (DivideByZeroException ex)
{
    Console.WriteLine("Cannot divide by zero!");
}
catch (Exception ex)
{
    Console.WriteLine($"An error occurred: {ex.Message}");
}
finally
{
    Console.WriteLine("Exiting program...");
}
```

In this example, we use a try-catch block to handle potential exceptions that may occur when dividing two integers entered by the user. We first attempt to parse the user input as integers using `int.Parse()`. If the input is invalid, a `FormatException` is thrown and caught by the first catch block. If the user attempts to divide by zero, a `DivideByZeroException` is thrown and caught by the second catch block. If any other exception occurs, it is caught by the third catch block, which handles all other exceptions. Finally, regardless of whether an exception is thrown or caught, the code in the `finally` the block is executed to clean up any resources and exit the program.

The `throw` the statement can also be used to explicitly throw an exception from within a method or property. For example:

```csharp
csharpCopy codepublic int Divide(int x, int y)
{
    if (y == 0)
    {
        throw new DivideByZeroException("Cannot divide by zero!");
    }

    return x / y;
}
```

In this example, the `Divide` method throws a `DivideByZeroException` if the second argument is zero, effectively preventing a runtime error when dividing by zero. This exception can be caught and handled using a try-catch block like in the previous example.